2024-12-01 09:30:08,115 : INFO : Start of Training
2024-12-01 09:30:08,116 : INFO : Run_id: 2024-12-01_093008_729953668
2024-12-01 09:30:08,116 : INFO : Start of Data Load, validation and transformation
2024-12-01 09:30:08,116 : INFO : Start of Archiving Old Rejected Files...
2024-12-01 09:30:08,116 : INFO : End of Archiving Old Rejected Files...
2024-12-01 09:30:08,116 : INFO : Start of Archiving Old Validated Files...
2024-12-01 09:30:08,120 : INFO : End of Archiving Old Validated Files...
2024-12-01 09:30:08,121 : INFO : Start of Archiving Old Processed Files...
2024-12-01 09:30:08,123 : INFO : End of Archiving Old Processed Files...
2024-12-01 09:30:08,123 : INFO : Start of Archiving Old Result Files...
2024-12-01 09:30:08,123 : INFO : End of Archiving Old Result Files...
2024-12-01 09:30:08,123 : INFO : Start of Reading values From Schema...
2024-12-01 09:30:08,124 : INFO : End of Reading values From Schema...
2024-12-01 09:30:08,124 : INFO : Start of Validating Column Length...
2024-12-01 09:30:08,124 : ERROR : OSError raised while Validating Column Length
Traceback (most recent call last):
  File "c:\Users\patel\Desktop\Projects2\endtoend-ml-projects-master\EndtoEndML_v11\apps\ingestion\load_validate.py", line 44, in validate_column_length
    for file in listdir(self.data_path):
                ^^^^^^^^^^^^^^^^^^^^^^^
FileNotFoundError: [WinError 3] The system cannot find the path specified: 'data/training_data'
2024-12-01 09:30:08,125 : ERROR : Unsuccessful End of Data Load, validation and transformation
Traceback (most recent call last):
  File "c:\Users\patel\Desktop\Projects2\endtoend-ml-projects-master\EndtoEndML_v11\apps\ingestion\load_validate.py", line 44, in validate_column_length
    for file in listdir(self.data_path):
                ^^^^^^^^^^^^^^^^^^^^^^^
FileNotFoundError: [WinError 3] The system cannot find the path specified: 'data/training_data'

During handling of the above exception, another exception occurred:

Traceback (most recent call last):
  File "c:\Users\patel\Desktop\Projects2\endtoend-ml-projects-master\EndtoEndML_v11\apps\ingestion\load_validate.py", line 191, in validate_trainset
    self.validate_column_length(number_of_columns)
  File "c:\Users\patel\Desktop\Projects2\endtoend-ml-projects-master\EndtoEndML_v11\apps\ingestion\load_validate.py", line 55, in validate_column_length
    raise OSError
OSError
2024-12-01 09:30:08,126 : ERROR : Unsuccessful End of Training
Traceback (most recent call last):
  File "c:\Users\patel\Desktop\Projects2\endtoend-ml-projects-master\EndtoEndML_v11\apps\ingestion\load_validate.py", line 44, in validate_column_length
    for file in listdir(self.data_path):
                ^^^^^^^^^^^^^^^^^^^^^^^
FileNotFoundError: [WinError 3] The system cannot find the path specified: 'data/training_data'

During handling of the above exception, another exception occurred:

Traceback (most recent call last):
  File "c:\Users\patel\Desktop\Projects2\endtoend-ml-projects-master\EndtoEndML_v11\apps\ingestion\load_validate.py", line 191, in validate_trainset
    self.validate_column_length(number_of_columns)
  File "c:\Users\patel\Desktop\Projects2\endtoend-ml-projects-master\EndtoEndML_v11\apps\ingestion\load_validate.py", line 55, in validate_column_length
    raise OSError
OSError

During handling of the above exception, another exception occurred:

Traceback (most recent call last):
  File "c:\Users\patel\Desktop\Projects2\endtoend-ml-projects-master\EndtoEndML_v11\apps\training\train_model.py", line 45, in training_model
    self.loadValidate.validate_trainset()
  File "c:\Users\patel\Desktop\Projects2\endtoend-ml-projects-master\EndtoEndML_v11\apps\ingestion\load_validate.py", line 207, in validate_trainset
    raise Exception
Exception
